Discovered worker type 'process' for work pool 
'local-process-work-pool-139fe23e'.
Worker 'ProcessWorker -- 00000000-0000-0000-0000-acde48001122 -- 210b' 
started!
Discovered worker type 'process' for work pool 
'local-process-work-pool-139fe23e'.
Worker 'ProcessWorker -- 00000000-0000-0000-0000-acde48001122 -- ec71' 
started!
09:02:13.630 | INFO    | prefect.flow_runs.worker - Worker 'ProcessWorker -- 00000000-0000-0000-0000-acde48001122 -- ec71' submitting flow run '4f5cadc0-eea5-49de-81ec-b71921d61c45'
09:02:13.972 | INFO    | prefect.flow_runs.worker - Opening process...
09:02:14.062 | INFO    | prefect.flow_runs.worker - Completed submission of flow run '4f5cadc0-eea5-49de-81ec-b71921d61c45'
/Users/marwansarieddine/.pyenv/versions/3.8.7/lib/python3.8/runpy.py:127: RuntimeWarning: 'prefect.engine' found in sys.modules after import of package 'prefect', but prior to execution of 'prefect.engine'; this may result in unpredictable behaviour
  warn(RuntimeWarning(msg))
09:02:18.156 | INFO    | Flow run 'merciful-aardwark' - Downloading flow code from storage at '/Users/marwansarieddine/open_source/marwan/meta-prefect/examples/local/script'
09:02:19.061 | INFO    | Flow run 'merciful-aardwark' - Running add_two_numbers_flow in env='dev'
09:02:19.061 | INFO    | Flow run 'merciful-aardwark' - out=17
09:02:19.182 | INFO    | Flow run 'merciful-aardwark' - Finished in state Completed()
09:02:19.534 | INFO    | prefect.flow_runs.worker - Process 95623 exited cleanly.
An exception occurred.
Traceback (most recent call last):
  File "/Users/marwansarieddine/.pyenv/versions/3.8.7/envs/meta-prefect-py38/lib/python3.8/site-packages/prefect/cli/_utilities.py", line 41, in wrapper
    return fn(*args, **kwargs)
  File "/Users/marwansarieddine/.pyenv/versions/3.8.7/envs/meta-prefect-py38/lib/python3.8/site-packages/prefect/utilities/asyncutils.py", line 255, in coroutine_wrapper
    return call()
  File "/Users/marwansarieddine/.pyenv/versions/3.8.7/envs/meta-prefect-py38/lib/python3.8/site-packages/prefect/_internal/concurrency/calls.py", line 383, in __call__
    return self.result()
  File "/Users/marwansarieddine/.pyenv/versions/3.8.7/envs/meta-prefect-py38/lib/python3.8/site-packages/prefect/_internal/concurrency/calls.py", line 283, in result
    return self.future.result(timeout=timeout)
  File "/Users/marwansarieddine/.pyenv/versions/3.8.7/envs/meta-prefect-py38/lib/python3.8/site-packages/prefect/_internal/concurrency/calls.py", line 169, in result
    return self.__get_result()
  File "/Users/marwansarieddine/.pyenv/versions/3.8.7/lib/python3.8/concurrent/futures/_base.py", line 388, in __get_result
    raise self._exception
  File "/Users/marwansarieddine/.pyenv/versions/3.8.7/envs/meta-prefect-py38/lib/python3.8/site-packages/prefect/_internal/concurrency/calls.py", line 346, in _run_async
    result = await coro
  File "/Users/marwansarieddine/.pyenv/versions/3.8.7/envs/meta-prefect-py38/lib/python3.8/site-packages/prefect/cli/worker.py", line 178, in start
    server_thread.start()
  File "/Users/marwansarieddine/.pyenv/versions/3.8.7/envs/meta-prefect-py38/lib/python3.8/site-packages/anyio/_backends/_asyncio.py", line 597, in __aexit__
    raise exceptions[0]
  File "/Users/marwansarieddine/.pyenv/versions/3.8.7/envs/meta-prefect-py38/lib/python3.8/site-packages/prefect/utilities/services.py", line 53, in critical_service_loop
    await workload()
  File "/Users/marwansarieddine/.pyenv/versions/3.8.7/envs/meta-prefect-py38/lib/python3.8/site-packages/prefect/workers/base.py", line 525, in get_and_submit_flow_runs
    runs_response = await self._get_scheduled_flow_runs()
  File "/Users/marwansarieddine/.pyenv/versions/3.8.7/envs/meta-prefect-py38/lib/python3.8/site-packages/prefect/workers/base.py", line 708, in _get_scheduled_flow_runs
    await self._client.get_scheduled_flow_runs_for_work_pool(
  File "/Users/marwansarieddine/.pyenv/versions/3.8.7/envs/meta-prefect-py38/lib/python3.8/site-packages/prefect/client/orchestration.py", line 2358, in get_scheduled_flow_runs_for_work_pool
    response = await self._client.post(
  File "/Users/marwansarieddine/.pyenv/versions/3.8.7/envs/meta-prefect-py38/lib/python3.8/site-packages/httpx/_client.py", line 1848, in post
    return await self.request(
  File "/Users/marwansarieddine/.pyenv/versions/3.8.7/envs/meta-prefect-py38/lib/python3.8/site-packages/httpx/_client.py", line 1530, in request
    return await self.send(request, auth=auth, follow_redirects=follow_redirects)
  File "/Users/marwansarieddine/.pyenv/versions/3.8.7/envs/meta-prefect-py38/lib/python3.8/site-packages/prefect/client/base.py", line 280, in send
    response.raise_for_status()
  File "/Users/marwansarieddine/.pyenv/versions/3.8.7/envs/meta-prefect-py38/lib/python3.8/site-packages/prefect/client/base.py", line 138, in raise_for_status
    raise PrefectHTTPStatusError.from_httpx_error(exc) from exc.__cause__
prefect.exceptions.PrefectHTTPStatusError: Client error '404 Not Found' for url 'https://api.prefect.cloud/api/accounts/d1953164-3137-486e-a3f4-c0317f542eff/workspaces/9921ae57-2d9b-45ba-9f5c-02f59d0f38de/work_pools/local-process-work-pool-139fe23e/get_scheduled_flow_runs'
Response: {'detail': 'Work pool "local-process-work-pool-139fe23e" not found.'}
For more information check: https://httpstatuses.com/404
An exception occurred.
Traceback (most recent call last):
  File "/Users/marwansarieddine/.pyenv/versions/3.8.7/envs/meta-prefect-py38/lib/python3.8/site-packages/prefect/cli/_utilities.py", line 41, in wrapper
    return fn(*args, **kwargs)
  File "/Users/marwansarieddine/.pyenv/versions/3.8.7/envs/meta-prefect-py38/lib/python3.8/site-packages/prefect/utilities/asyncutils.py", line 255, in coroutine_wrapper
    return call()
  File "/Users/marwansarieddine/.pyenv/versions/3.8.7/envs/meta-prefect-py38/lib/python3.8/site-packages/prefect/_internal/concurrency/calls.py", line 383, in __call__
    return self.result()
  File "/Users/marwansarieddine/.pyenv/versions/3.8.7/envs/meta-prefect-py38/lib/python3.8/site-packages/prefect/_internal/concurrency/calls.py", line 283, in result
    return self.future.result(timeout=timeout)
  File "/Users/marwansarieddine/.pyenv/versions/3.8.7/envs/meta-prefect-py38/lib/python3.8/site-packages/prefect/_internal/concurrency/calls.py", line 169, in result
    return self.__get_result()
  File "/Users/marwansarieddine/.pyenv/versions/3.8.7/lib/python3.8/concurrent/futures/_base.py", line 388, in __get_result
    raise self._exception
  File "/Users/marwansarieddine/.pyenv/versions/3.8.7/envs/meta-prefect-py38/lib/python3.8/site-packages/prefect/_internal/concurrency/calls.py", line 346, in _run_async
    result = await coro
  File "/Users/marwansarieddine/.pyenv/versions/3.8.7/envs/meta-prefect-py38/lib/python3.8/site-packages/prefect/cli/worker.py", line 178, in start
    server_thread.start()
  File "/Users/marwansarieddine/.pyenv/versions/3.8.7/envs/meta-prefect-py38/lib/python3.8/site-packages/anyio/_backends/_asyncio.py", line 597, in __aexit__
    raise exceptions[0]
  File "/Users/marwansarieddine/.pyenv/versions/3.8.7/envs/meta-prefect-py38/lib/python3.8/site-packages/prefect/utilities/services.py", line 53, in critical_service_loop
    await workload()
  File "/Users/marwansarieddine/.pyenv/versions/3.8.7/envs/meta-prefect-py38/lib/python3.8/site-packages/prefect/workers/base.py", line 525, in get_and_submit_flow_runs
    runs_response = await self._get_scheduled_flow_runs()
  File "/Users/marwansarieddine/.pyenv/versions/3.8.7/envs/meta-prefect-py38/lib/python3.8/site-packages/prefect/workers/base.py", line 708, in _get_scheduled_flow_runs
    await self._client.get_scheduled_flow_runs_for_work_pool(
  File "/Users/marwansarieddine/.pyenv/versions/3.8.7/envs/meta-prefect-py38/lib/python3.8/site-packages/prefect/client/orchestration.py", line 2358, in get_scheduled_flow_runs_for_work_pool
    response = await self._client.post(
  File "/Users/marwansarieddine/.pyenv/versions/3.8.7/envs/meta-prefect-py38/lib/python3.8/site-packages/httpx/_client.py", line 1848, in post
    return await self.request(
  File "/Users/marwansarieddine/.pyenv/versions/3.8.7/envs/meta-prefect-py38/lib/python3.8/site-packages/httpx/_client.py", line 1530, in request
    return await self.send(request, auth=auth, follow_redirects=follow_redirects)
  File "/Users/marwansarieddine/.pyenv/versions/3.8.7/envs/meta-prefect-py38/lib/python3.8/site-packages/prefect/client/base.py", line 280, in send
    response.raise_for_status()
  File "/Users/marwansarieddine/.pyenv/versions/3.8.7/envs/meta-prefect-py38/lib/python3.8/site-packages/prefect/client/base.py", line 138, in raise_for_status
    raise PrefectHTTPStatusError.from_httpx_error(exc) from exc.__cause__
prefect.exceptions.PrefectHTTPStatusError: Client error '404 Not Found' for url 'https://api.prefect.cloud/api/accounts/d1953164-3137-486e-a3f4-c0317f542eff/workspaces/9921ae57-2d9b-45ba-9f5c-02f59d0f38de/work_pools/local-process-work-pool-139fe23e/get_scheduled_flow_runs'
Response: {'detail': 'Work pool "local-process-work-pool-139fe23e" not found.'}
For more information check: https://httpstatuses.com/404
Discovered worker type 'process' for work pool 'local-process-work-pool-34a8d08f'.
Worker 'ProcessWorker -- 00000000-0000-0000-0000-acde48001122 -- e00c' started!
Discovered worker type 'process' for work pool 'local-process-work-pool-34a8d08f'.
Worker 'ProcessWorker -- 00000000-0000-0000-0000-acde48001122 -- af26' started!
Discovered worker type 'process' for work pool 'local-process-work-pool-34a8d08f'.
Worker 'ProcessWorker -- 00000000-0000-0000-0000-acde48001122 -- 8445' started!
16:42:06.706 | INFO    | prefect.flow_runs.worker - Worker 'ProcessWorker -- 00000000-0000-0000-0000-acde48001122 -- af26' submitting flow run 'c1a4eb13-2872-4dfc-a9a9-60dd33b854ab'
16:42:07.169 | INFO    | prefect.flow_runs.worker - Opening process...
16:42:07.253 | INFO    | prefect.flow_runs.worker - Completed submission of flow run 'c1a4eb13-2872-4dfc-a9a9-60dd33b854ab'
/Users/marwansarieddine/.pyenv/versions/3.8.7/lib/python3.8/runpy.py:127: RuntimeWarning: 'prefect.engine' found in sys.modules after import of package 'prefect', but prior to execution of 'prefect.engine'; this may result in unpredictable behaviour
  warn(RuntimeWarning(msg))
16:42:11.290 | INFO    | Flow run 'hilarious-cricket' - Downloading flow code from storage at '/Users/marwansarieddine/open_source/marwan/meta-prefect/examples/local/script'
16:42:12.030 | INFO    | Flow run 'hilarious-cricket' - Running add_two_numbers_flow in env='dev'
16:42:12.031 | INFO    | Flow run 'hilarious-cricket' - out=2
16:42:12.162 | INFO    | Flow run 'hilarious-cricket' - Finished in state Completed()
16:42:12.700 | INFO    | prefect.flow_runs.worker - Process 36017 exited cleanly.
An exception occurred.
Traceback (most recent call last):
  File "/Users/marwansarieddine/.pyenv/versions/3.8.7/envs/meta-prefect-py38/lib/python3.8/site-packages/prefect/cli/_utilities.py", line 41, in wrapper
    return fn(*args, **kwargs)
  File "/Users/marwansarieddine/.pyenv/versions/3.8.7/envs/meta-prefect-py38/lib/python3.8/site-packages/prefect/utilities/asyncutils.py", line 255, in coroutine_wrapper
    return call()
  File "/Users/marwansarieddine/.pyenv/versions/3.8.7/envs/meta-prefect-py38/lib/python3.8/site-packages/prefect/_internal/concurrency/calls.py", line 383, in __call__
    return self.result()
  File "/Users/marwansarieddine/.pyenv/versions/3.8.7/envs/meta-prefect-py38/lib/python3.8/site-packages/prefect/_internal/concurrency/calls.py", line 283, in result
    return self.future.result(timeout=timeout)
  File "/Users/marwansarieddine/.pyenv/versions/3.8.7/envs/meta-prefect-py38/lib/python3.8/site-packages/prefect/_internal/concurrency/calls.py", line 169, in result
    return self.__get_result()
  File "/Users/marwansarieddine/.pyenv/versions/3.8.7/lib/python3.8/concurrent/futures/_base.py", line 388, in __get_result
    raise self._exception
  File "/Users/marwansarieddine/.pyenv/versions/3.8.7/envs/meta-prefect-py38/lib/python3.8/site-packages/prefect/_internal/concurrency/calls.py", line 346, in _run_async
    result = await coro
  File "/Users/marwansarieddine/.pyenv/versions/3.8.7/envs/meta-prefect-py38/lib/python3.8/site-packages/prefect/cli/worker.py", line 178, in start
    server_thread.start()
  File "/Users/marwansarieddine/.pyenv/versions/3.8.7/envs/meta-prefect-py38/lib/python3.8/site-packages/anyio/_backends/_asyncio.py", line 597, in __aexit__
    raise exceptions[0]
  File "/Users/marwansarieddine/.pyenv/versions/3.8.7/envs/meta-prefect-py38/lib/python3.8/site-packages/prefect/utilities/services.py", line 53, in critical_service_loop
    await workload()
  File "/Users/marwansarieddine/.pyenv/versions/3.8.7/envs/meta-prefect-py38/lib/python3.8/site-packages/prefect/workers/base.py", line 525, in get_and_submit_flow_runs
    runs_response = await self._get_scheduled_flow_runs()
  File "/Users/marwansarieddine/.pyenv/versions/3.8.7/envs/meta-prefect-py38/lib/python3.8/site-packages/prefect/workers/base.py", line 708, in _get_scheduled_flow_runs
    await self._client.get_scheduled_flow_runs_for_work_pool(
  File "/Users/marwansarieddine/.pyenv/versions/3.8.7/envs/meta-prefect-py38/lib/python3.8/site-packages/prefect/client/orchestration.py", line 2358, in get_scheduled_flow_runs_for_work_pool
    response = await self._client.post(
  File "/Users/marwansarieddine/.pyenv/versions/3.8.7/envs/meta-prefect-py38/lib/python3.8/site-packages/httpx/_client.py", line 1848, in post
    return await self.request(
  File "/Users/marwansarieddine/.pyenv/versions/3.8.7/envs/meta-prefect-py38/lib/python3.8/site-packages/httpx/_client.py", line 1530, in request
    return await self.send(request, auth=auth, follow_redirects=follow_redirects)
  File "/Users/marwansarieddine/.pyenv/versions/3.8.7/envs/meta-prefect-py38/lib/python3.8/site-packages/prefect/client/base.py", line 280, in send
    response.raise_for_status()
  File "/Users/marwansarieddine/.pyenv/versions/3.8.7/envs/meta-prefect-py38/lib/python3.8/site-packages/prefect/client/base.py", line 138, in raise_for_status
    raise PrefectHTTPStatusError.from_httpx_error(exc) from exc.__cause__
prefect.exceptions.PrefectHTTPStatusError: Client error '404 Not Found' for url 'https://api.prefect.cloud/api/accounts/d1953164-3137-486e-a3f4-c0317f542eff/workspaces/9921ae57-2d9b-45ba-9f5c-02f59d0f38de/work_pools/local-process-work-pool-34a8d08f/get_scheduled_flow_runs'
Response: {'detail': 'Work pool "local-process-work-pool-34a8d08f" not found.'}
For more information check: https://httpstatuses.com/404
An exception occurred.
Traceback (most recent call last):
  File "/Users/marwansarieddine/.pyenv/versions/3.8.7/envs/meta-prefect-py38/lib/python3.8/site-packages/prefect/cli/_utilities.py", line 41, in wrapper
    return fn(*args, **kwargs)
  File "/Users/marwansarieddine/.pyenv/versions/3.8.7/envs/meta-prefect-py38/lib/python3.8/site-packages/prefect/utilities/asyncutils.py", line 255, in coroutine_wrapper
    return call()
  File "/Users/marwansarieddine/.pyenv/versions/3.8.7/envs/meta-prefect-py38/lib/python3.8/site-packages/prefect/_internal/concurrency/calls.py", line 383, in __call__
    return self.result()
  File "/Users/marwansarieddine/.pyenv/versions/3.8.7/envs/meta-prefect-py38/lib/python3.8/site-packages/prefect/_internal/concurrency/calls.py", line 283, in result
    return self.future.result(timeout=timeout)
  File "/Users/marwansarieddine/.pyenv/versions/3.8.7/envs/meta-prefect-py38/lib/python3.8/site-packages/prefect/_internal/concurrency/calls.py", line 169, in result
    return self.__get_result()
  File "/Users/marwansarieddine/.pyenv/versions/3.8.7/lib/python3.8/concurrent/futures/_base.py", line 388, in __get_result
    raise self._exception
  File "/Users/marwansarieddine/.pyenv/versions/3.8.7/envs/meta-prefect-py38/lib/python3.8/site-packages/prefect/_internal/concurrency/calls.py", line 346, in _run_async
    result = await coro
  File "/Users/marwansarieddine/.pyenv/versions/3.8.7/envs/meta-prefect-py38/lib/python3.8/site-packages/prefect/cli/worker.py", line 178, in start
    server_thread.start()
  File "/Users/marwansarieddine/.pyenv/versions/3.8.7/envs/meta-prefect-py38/lib/python3.8/site-packages/anyio/_backends/_asyncio.py", line 597, in __aexit__
    raise exceptions[0]
  File "/Users/marwansarieddine/.pyenv/versions/3.8.7/envs/meta-prefect-py38/lib/python3.8/site-packages/prefect/utilities/services.py", line 53, in critical_service_loop
    await workload()
  File "/Users/marwansarieddine/.pyenv/versions/3.8.7/envs/meta-prefect-py38/lib/python3.8/site-packages/prefect/workers/base.py", line 525, in get_and_submit_flow_runs
    runs_response = await self._get_scheduled_flow_runs()
  File "/Users/marwansarieddine/.pyenv/versions/3.8.7/envs/meta-prefect-py38/lib/python3.8/site-packages/prefect/workers/base.py", line 708, in _get_scheduled_flow_runs
    await self._client.get_scheduled_flow_runs_for_work_pool(
  File "/Users/marwansarieddine/.pyenv/versions/3.8.7/envs/meta-prefect-py38/lib/python3.8/site-packages/prefect/client/orchestration.py", line 2358, in get_scheduled_flow_runs_for_work_pool
    response = await self._client.post(
  File "/Users/marwansarieddine/.pyenv/versions/3.8.7/envs/meta-prefect-py38/lib/python3.8/site-packages/httpx/_client.py", line 1848, in post
    return await self.request(
  File "/Users/marwansarieddine/.pyenv/versions/3.8.7/envs/meta-prefect-py38/lib/python3.8/site-packages/httpx/_client.py", line 1530, in request
    return await self.send(request, auth=auth, follow_redirects=follow_redirects)
  File "/Users/marwansarieddine/.pyenv/versions/3.8.7/envs/meta-prefect-py38/lib/python3.8/site-packages/prefect/client/base.py", line 280, in send
    response.raise_for_status()
  File "/Users/marwansarieddine/.pyenv/versions/3.8.7/envs/meta-prefect-py38/lib/python3.8/site-packages/prefect/client/base.py", line 138, in raise_for_status
    raise PrefectHTTPStatusError.from_httpx_error(exc) from exc.__cause__
prefect.exceptions.PrefectHTTPStatusError: Client error '404 Not Found' for url 'https://api.prefect.cloud/api/accounts/d1953164-3137-486e-a3f4-c0317f542eff/workspaces/9921ae57-2d9b-45ba-9f5c-02f59d0f38de/work_pools/local-process-work-pool-34a8d08f/get_scheduled_flow_runs'
Response: {'detail': 'Work pool "local-process-work-pool-34a8d08f" not found.'}
For more information check: https://httpstatuses.com/404
16:45:54.794 | INFO    | prefect.worker.process.processworker -- 00000000-0000-0000-0000-acde48001122 -- e00c - Worker pool 'local-process-work-pool-34a8d08f' created.
An exception occurred.
Traceback (most recent call last):
  File "/Users/marwansarieddine/.pyenv/versions/3.8.7/envs/meta-prefect-py38/lib/python3.8/site-packages/prefect/cli/_utilities.py", line 41, in wrapper
    return fn(*args, **kwargs)
  File "/Users/marwansarieddine/.pyenv/versions/3.8.7/envs/meta-prefect-py38/lib/python3.8/site-packages/prefect/utilities/asyncutils.py", line 255, in coroutine_wrapper
    return call()
  File "/Users/marwansarieddine/.pyenv/versions/3.8.7/envs/meta-prefect-py38/lib/python3.8/site-packages/prefect/_internal/concurrency/calls.py", line 383, in __call__
    return self.result()
  File "/Users/marwansarieddine/.pyenv/versions/3.8.7/envs/meta-prefect-py38/lib/python3.8/site-packages/prefect/_internal/concurrency/calls.py", line 283, in result
    return self.future.result(timeout=timeout)
  File "/Users/marwansarieddine/.pyenv/versions/3.8.7/envs/meta-prefect-py38/lib/python3.8/site-packages/prefect/_internal/concurrency/calls.py", line 169, in result
    return self.__get_result()
  File "/Users/marwansarieddine/.pyenv/versions/3.8.7/lib/python3.8/concurrent/futures/_base.py", line 388, in __get_result
    raise self._exception
  File "/Users/marwansarieddine/.pyenv/versions/3.8.7/envs/meta-prefect-py38/lib/python3.8/site-packages/prefect/_internal/concurrency/calls.py", line 346, in _run_async
    result = await coro
  File "/Users/marwansarieddine/.pyenv/versions/3.8.7/envs/meta-prefect-py38/lib/python3.8/site-packages/prefect/cli/worker.py", line 178, in start
    server_thread.start()
  File "/Users/marwansarieddine/.pyenv/versions/3.8.7/envs/meta-prefect-py38/lib/python3.8/site-packages/anyio/_backends/_asyncio.py", line 597, in __aexit__
    raise exceptions[0]
  File "/Users/marwansarieddine/.pyenv/versions/3.8.7/envs/meta-prefect-py38/lib/python3.8/site-packages/prefect/utilities/services.py", line 53, in critical_service_loop
    await workload()
  File "/Users/marwansarieddine/.pyenv/versions/3.8.7/envs/meta-prefect-py38/lib/python3.8/site-packages/prefect/workers/base.py", line 525, in get_and_submit_flow_runs
    runs_response = await self._get_scheduled_flow_runs()
  File "/Users/marwansarieddine/.pyenv/versions/3.8.7/envs/meta-prefect-py38/lib/python3.8/site-packages/prefect/workers/base.py", line 708, in _get_scheduled_flow_runs
    await self._client.get_scheduled_flow_runs_for_work_pool(
  File "/Users/marwansarieddine/.pyenv/versions/3.8.7/envs/meta-prefect-py38/lib/python3.8/site-packages/prefect/client/orchestration.py", line 2358, in get_scheduled_flow_runs_for_work_pool
    response = await self._client.post(
  File "/Users/marwansarieddine/.pyenv/versions/3.8.7/envs/meta-prefect-py38/lib/python3.8/site-packages/httpx/_client.py", line 1848, in post
    return await self.request(
  File "/Users/marwansarieddine/.pyenv/versions/3.8.7/envs/meta-prefect-py38/lib/python3.8/site-packages/httpx/_client.py", line 1530, in request
    return await self.send(request, auth=auth, follow_redirects=follow_redirects)
  File "/Users/marwansarieddine/.pyenv/versions/3.8.7/envs/meta-prefect-py38/lib/python3.8/site-packages/prefect/client/base.py", line 280, in send
    response.raise_for_status()
  File "/Users/marwansarieddine/.pyenv/versions/3.8.7/envs/meta-prefect-py38/lib/python3.8/site-packages/prefect/client/base.py", line 138, in raise_for_status
    raise PrefectHTTPStatusError.from_httpx_error(exc) from exc.__cause__
prefect.exceptions.PrefectHTTPStatusError: Client error '404 Not Found' for url 'https://api.prefect.cloud/api/accounts/d1953164-3137-486e-a3f4-c0317f542eff/workspaces/9921ae57-2d9b-45ba-9f5c-02f59d0f38de/work_pools/local-process-work-pool-34a8d08f/get_scheduled_flow_runs'
Response: {'detail': 'Work pool "local-process-work-pool-34a8d08f" not found.'}
For more information check: https://httpstatuses.com/404
Discovered worker type 'process' for work pool 'local-process-work-pool-46089f44'.
Worker 'ProcessWorker -- 00000000-0000-0000-0000-acde48001122 -- d221' started!
Discovered worker type 'process' for work pool 'local-process-work-pool-46089f44'.
Worker 'ProcessWorker -- 00000000-0000-0000-0000-acde48001122 -- 4502' started!
Discovered worker type 'process' for work pool 'local-process-work-pool-46089f44'.
Worker 'ProcessWorker -- 00000000-0000-0000-0000-acde48001122 -- fdff' started!
An exception occurred.
Traceback (most recent call last):
  File "/Users/marwansarieddine/.pyenv/versions/3.8.7/envs/meta-prefect-py38/lib/python3.8/site-packages/prefect/cli/_utilities.py", line 41, in wrapper
    return fn(*args, **kwargs)
  File "/Users/marwansarieddine/.pyenv/versions/3.8.7/envs/meta-prefect-py38/lib/python3.8/site-packages/prefect/utilities/asyncutils.py", line 255, in coroutine_wrapper
    return call()
  File "/Users/marwansarieddine/.pyenv/versions/3.8.7/envs/meta-prefect-py38/lib/python3.8/site-packages/prefect/_internal/concurrency/calls.py", line 383, in __call__
    return self.result()
  File "/Users/marwansarieddine/.pyenv/versions/3.8.7/envs/meta-prefect-py38/lib/python3.8/site-packages/prefect/_internal/concurrency/calls.py", line 283, in result
    return self.future.result(timeout=timeout)
  File "/Users/marwansarieddine/.pyenv/versions/3.8.7/envs/meta-prefect-py38/lib/python3.8/site-packages/prefect/_internal/concurrency/calls.py", line 169, in result
    return self.__get_result()
  File "/Users/marwansarieddine/.pyenv/versions/3.8.7/lib/python3.8/concurrent/futures/_base.py", line 388, in __get_result
    raise self._exception
  File "/Users/marwansarieddine/.pyenv/versions/3.8.7/envs/meta-prefect-py38/lib/python3.8/site-packages/prefect/_internal/concurrency/calls.py", line 346, in _run_async
    result = await coro
  File "/Users/marwansarieddine/.pyenv/versions/3.8.7/envs/meta-prefect-py38/lib/python3.8/site-packages/prefect/cli/worker.py", line 178, in start
    server_thread.start()
  File "/Users/marwansarieddine/.pyenv/versions/3.8.7/envs/meta-prefect-py38/lib/python3.8/site-packages/anyio/_backends/_asyncio.py", line 597, in __aexit__
    raise exceptions[0]
  File "/Users/marwansarieddine/.pyenv/versions/3.8.7/envs/meta-prefect-py38/lib/python3.8/site-packages/prefect/utilities/services.py", line 53, in critical_service_loop
    await workload()
  File "/Users/marwansarieddine/.pyenv/versions/3.8.7/envs/meta-prefect-py38/lib/python3.8/site-packages/prefect/workers/base.py", line 525, in get_and_submit_flow_runs
    runs_response = await self._get_scheduled_flow_runs()
  File "/Users/marwansarieddine/.pyenv/versions/3.8.7/envs/meta-prefect-py38/lib/python3.8/site-packages/prefect/workers/base.py", line 708, in _get_scheduled_flow_runs
    await self._client.get_scheduled_flow_runs_for_work_pool(
  File "/Users/marwansarieddine/.pyenv/versions/3.8.7/envs/meta-prefect-py38/lib/python3.8/site-packages/prefect/client/orchestration.py", line 2358, in get_scheduled_flow_runs_for_work_pool
    response = await self._client.post(
  File "/Users/marwansarieddine/.pyenv/versions/3.8.7/envs/meta-prefect-py38/lib/python3.8/site-packages/httpx/_client.py", line 1848, in post
    return await self.request(
  File "/Users/marwansarieddine/.pyenv/versions/3.8.7/envs/meta-prefect-py38/lib/python3.8/site-packages/httpx/_client.py", line 1530, in request
    return await self.send(request, auth=auth, follow_redirects=follow_redirects)
  File "/Users/marwansarieddine/.pyenv/versions/3.8.7/envs/meta-prefect-py38/lib/python3.8/site-packages/prefect/client/base.py", line 280, in send
    response.raise_for_status()
  File "/Users/marwansarieddine/.pyenv/versions/3.8.7/envs/meta-prefect-py38/lib/python3.8/site-packages/prefect/client/base.py", line 138, in raise_for_status
    raise PrefectHTTPStatusError.from_httpx_error(exc) from exc.__cause__
prefect.exceptions.PrefectHTTPStatusError: Client error '404 Not Found' for url 'https://api.prefect.cloud/api/accounts/d1953164-3137-486e-a3f4-c0317f542eff/workspaces/9921ae57-2d9b-45ba-9f5c-02f59d0f38de/work_pools/local-process-work-pool-46089f44/get_scheduled_flow_runs'
Response: {'detail': 'Work pool "local-process-work-pool-46089f44" not found.'}
For more information check: https://httpstatuses.com/404
An exception occurred.
Traceback (most recent call last):
  File "/Users/marwansarieddine/.pyenv/versions/3.8.7/envs/meta-prefect-py38/lib/python3.8/site-packages/prefect/cli/_utilities.py", line 41, in wrapper
    return fn(*args, **kwargs)
  File "/Users/marwansarieddine/.pyenv/versions/3.8.7/envs/meta-prefect-py38/lib/python3.8/site-packages/prefect/utilities/asyncutils.py", line 255, in coroutine_wrapper
    return call()
  File "/Users/marwansarieddine/.pyenv/versions/3.8.7/envs/meta-prefect-py38/lib/python3.8/site-packages/prefect/_internal/concurrency/calls.py", line 383, in __call__
    return self.result()
  File "/Users/marwansarieddine/.pyenv/versions/3.8.7/envs/meta-prefect-py38/lib/python3.8/site-packages/prefect/_internal/concurrency/calls.py", line 283, in result
    return self.future.result(timeout=timeout)
  File "/Users/marwansarieddine/.pyenv/versions/3.8.7/envs/meta-prefect-py38/lib/python3.8/site-packages/prefect/_internal/concurrency/calls.py", line 169, in result
    return self.__get_result()
  File "/Users/marwansarieddine/.pyenv/versions/3.8.7/lib/python3.8/concurrent/futures/_base.py", line 388, in __get_result
    raise self._exception
  File "/Users/marwansarieddine/.pyenv/versions/3.8.7/envs/meta-prefect-py38/lib/python3.8/site-packages/prefect/_internal/concurrency/calls.py", line 346, in _run_async
    result = await coro
  File "/Users/marwansarieddine/.pyenv/versions/3.8.7/envs/meta-prefect-py38/lib/python3.8/site-packages/prefect/cli/worker.py", line 178, in start
    server_thread.start()
  File "/Users/marwansarieddine/.pyenv/versions/3.8.7/envs/meta-prefect-py38/lib/python3.8/site-packages/anyio/_backends/_asyncio.py", line 597, in __aexit__
    raise exceptions[0]
  File "/Users/marwansarieddine/.pyenv/versions/3.8.7/envs/meta-prefect-py38/lib/python3.8/site-packages/prefect/utilities/services.py", line 53, in critical_service_loop
    await workload()
  File "/Users/marwansarieddine/.pyenv/versions/3.8.7/envs/meta-prefect-py38/lib/python3.8/site-packages/prefect/workers/base.py", line 525, in get_and_submit_flow_runs
    runs_response = await self._get_scheduled_flow_runs()
  File "/Users/marwansarieddine/.pyenv/versions/3.8.7/envs/meta-prefect-py38/lib/python3.8/site-packages/prefect/workers/base.py", line 708, in _get_scheduled_flow_runs
    await self._client.get_scheduled_flow_runs_for_work_pool(
  File "/Users/marwansarieddine/.pyenv/versions/3.8.7/envs/meta-prefect-py38/lib/python3.8/site-packages/prefect/client/orchestration.py", line 2358, in get_scheduled_flow_runs_for_work_pool
    response = await self._client.post(
  File "/Users/marwansarieddine/.pyenv/versions/3.8.7/envs/meta-prefect-py38/lib/python3.8/site-packages/httpx/_client.py", line 1848, in post
    return await self.request(
  File "/Users/marwansarieddine/.pyenv/versions/3.8.7/envs/meta-prefect-py38/lib/python3.8/site-packages/httpx/_client.py", line 1530, in request
    return await self.send(request, auth=auth, follow_redirects=follow_redirects)
  File "/Users/marwansarieddine/.pyenv/versions/3.8.7/envs/meta-prefect-py38/lib/python3.8/site-packages/prefect/client/base.py", line 280, in send
    response.raise_for_status()
  File "/Users/marwansarieddine/.pyenv/versions/3.8.7/envs/meta-prefect-py38/lib/python3.8/site-packages/prefect/client/base.py", line 138, in raise_for_status
    raise PrefectHTTPStatusError.from_httpx_error(exc) from exc.__cause__
prefect.exceptions.PrefectHTTPStatusError: Client error '404 Not Found' for url 'https://api.prefect.cloud/api/accounts/d1953164-3137-486e-a3f4-c0317f542eff/workspaces/9921ae57-2d9b-45ba-9f5c-02f59d0f38de/work_pools/local-process-work-pool-46089f44/get_scheduled_flow_runs'
Response: {'detail': 'Work pool "local-process-work-pool-46089f44" not found.'}
For more information check: https://httpstatuses.com/404
An exception occurred.
Traceback (most recent call last):
  File "/Users/marwansarieddine/.pyenv/versions/3.8.7/envs/meta-prefect-py38/lib/python3.8/site-packages/prefect/cli/_utilities.py", line 41, in wrapper
    return fn(*args, **kwargs)
  File "/Users/marwansarieddine/.pyenv/versions/3.8.7/envs/meta-prefect-py38/lib/python3.8/site-packages/prefect/utilities/asyncutils.py", line 255, in coroutine_wrapper
    return call()
  File "/Users/marwansarieddine/.pyenv/versions/3.8.7/envs/meta-prefect-py38/lib/python3.8/site-packages/prefect/_internal/concurrency/calls.py", line 383, in __call__
    return self.result()
  File "/Users/marwansarieddine/.pyenv/versions/3.8.7/envs/meta-prefect-py38/lib/python3.8/site-packages/prefect/_internal/concurrency/calls.py", line 283, in result
    return self.future.result(timeout=timeout)
  File "/Users/marwansarieddine/.pyenv/versions/3.8.7/envs/meta-prefect-py38/lib/python3.8/site-packages/prefect/_internal/concurrency/calls.py", line 169, in result
    return self.__get_result()
  File "/Users/marwansarieddine/.pyenv/versions/3.8.7/lib/python3.8/concurrent/futures/_base.py", line 388, in __get_result
    raise self._exception
  File "/Users/marwansarieddine/.pyenv/versions/3.8.7/envs/meta-prefect-py38/lib/python3.8/site-packages/prefect/_internal/concurrency/calls.py", line 346, in _run_async
    result = await coro
  File "/Users/marwansarieddine/.pyenv/versions/3.8.7/envs/meta-prefect-py38/lib/python3.8/site-packages/prefect/cli/worker.py", line 178, in start
    server_thread.start()
  File "/Users/marwansarieddine/.pyenv/versions/3.8.7/envs/meta-prefect-py38/lib/python3.8/site-packages/anyio/_backends/_asyncio.py", line 597, in __aexit__
    raise exceptions[0]
  File "/Users/marwansarieddine/.pyenv/versions/3.8.7/envs/meta-prefect-py38/lib/python3.8/site-packages/prefect/utilities/services.py", line 53, in critical_service_loop
    await workload()
  File "/Users/marwansarieddine/.pyenv/versions/3.8.7/envs/meta-prefect-py38/lib/python3.8/site-packages/prefect/workers/base.py", line 525, in get_and_submit_flow_runs
    runs_response = await self._get_scheduled_flow_runs()
  File "/Users/marwansarieddine/.pyenv/versions/3.8.7/envs/meta-prefect-py38/lib/python3.8/site-packages/prefect/workers/base.py", line 708, in _get_scheduled_flow_runs
    await self._client.get_scheduled_flow_runs_for_work_pool(
  File "/Users/marwansarieddine/.pyenv/versions/3.8.7/envs/meta-prefect-py38/lib/python3.8/site-packages/prefect/client/orchestration.py", line 2358, in get_scheduled_flow_runs_for_work_pool
    response = await self._client.post(
  File "/Users/marwansarieddine/.pyenv/versions/3.8.7/envs/meta-prefect-py38/lib/python3.8/site-packages/httpx/_client.py", line 1848, in post
    return await self.request(
  File "/Users/marwansarieddine/.pyenv/versions/3.8.7/envs/meta-prefect-py38/lib/python3.8/site-packages/httpx/_client.py", line 1530, in request
    return await self.send(request, auth=auth, follow_redirects=follow_redirects)
  File "/Users/marwansarieddine/.pyenv/versions/3.8.7/envs/meta-prefect-py38/lib/python3.8/site-packages/prefect/client/base.py", line 280, in send
    response.raise_for_status()
  File "/Users/marwansarieddine/.pyenv/versions/3.8.7/envs/meta-prefect-py38/lib/python3.8/site-packages/prefect/client/base.py", line 138, in raise_for_status
    raise PrefectHTTPStatusError.from_httpx_error(exc) from exc.__cause__
prefect.exceptions.PrefectHTTPStatusError: Client error '404 Not Found' for url 'https://api.prefect.cloud/api/accounts/d1953164-3137-486e-a3f4-c0317f542eff/workspaces/9921ae57-2d9b-45ba-9f5c-02f59d0f38de/work_pools/local-process-work-pool-46089f44/get_scheduled_flow_runs'
Response: {'detail': 'Work pool "local-process-work-pool-46089f44" not found.'}
For more information check: https://httpstatuses.com/404
Discovered worker type 'process' for work pool 'local-process-work-pool-6da5fdd6'.
Worker 'ProcessWorker -- 00000000-0000-0000-0000-acde48001122 -- fd13' started!
Discovered worker type 'process' for work pool 'local-process-work-pool-6da5fdd6'.
Worker 'ProcessWorker -- 00000000-0000-0000-0000-acde48001122 -- b0d0' started!
Discovered worker type 'process' for work pool 'local-process-work-pool-6da5fdd6'.
Worker 'ProcessWorker -- 00000000-0000-0000-0000-acde48001122 -- 2eec' started!
17:23:49.096 | INFO    | prefect.flow_runs.worker - Worker 'ProcessWorker -- 00000000-0000-0000-0000-acde48001122 -- 2eec' submitting flow run '0812796a-3961-4c3d-bf64-7a931f0195ea'
17:23:49.531 | INFO    | prefect.flow_runs.worker - Opening process...
17:23:49.632 | INFO    | prefect.flow_runs.worker - Completed submission of flow run '0812796a-3961-4c3d-bf64-7a931f0195ea'
/Users/marwansarieddine/.pyenv/versions/3.8.7/lib/python3.8/runpy.py:127: RuntimeWarning: 'prefect.engine' found in sys.modules after import of package 'prefect', but prior to execution of 'prefect.engine'; this may result in unpredictable behaviour
  warn(RuntimeWarning(msg))
17:23:53.877 | INFO    | Flow run 'optimal-kagu' - Downloading flow code from storage at '/Users/marwansarieddine/open_source/marwan/meta-prefect/examples/local/script'
17:23:55.051 | INFO    | Flow run 'optimal-kagu' - Running add_two_numbers_flow in env='dev'
17:23:55.052 | INFO    | Flow run 'optimal-kagu' - out=-6
17:23:55.771 | INFO    | Flow run 'optimal-kagu' - Finished in state Completed()
17:23:56.251 | INFO    | prefect.flow_runs.worker - Process 41076 exited cleanly.
03:30:06.689 | INFO    | prefect.flow_runs.worker - Worker 'ProcessWorker -- 00000000-0000-0000-0000-acde48001122 -- fd13' submitting flow run '7165aef0-ce94-4179-82bf-8328625ea03a'
03:30:07.612 | INFO    | prefect.flow_runs.worker - Opening process...
03:30:07.739 | INFO    | prefect.flow_runs.worker - Completed submission of flow run '7165aef0-ce94-4179-82bf-8328625ea03a'
/Users/marwansarieddine/.pyenv/versions/3.8.7/lib/python3.8/runpy.py:127: RuntimeWarning: 'prefect.engine' found in sys.modules after import of package 'prefect', but prior to execution of 'prefect.engine'; this may result in unpredictable behaviour
  warn(RuntimeWarning(msg))
03:30:13.236 | INFO    | Flow run 'aloof-chipmunk' - Downloading flow code from storage at '/Users/marwansarieddine/open_source/marwan/meta-prefect/examples/local/script'
03:30:13.331 | ERROR   | Flow run 'aloof-chipmunk' - Validation of flow parameters failed with error:
Traceback (most recent call last):
  File "/Users/marwansarieddine/.pyenv/versions/3.8.7/envs/meta-prefect-py38/lib/python3.8/site-packages/prefect/engine.py", line 423, in retrieve_flow_then_begin_flow_run
    parameters = flow.validate_parameters(flow_run.parameters)
  File "/Users/marwansarieddine/.pyenv/versions/3.8.7/envs/meta-prefect-py38/lib/python3.8/site-packages/prefect/flows.py", line 423, in validate_parameters
    raise ParameterTypeError.from_validation_error(exc) from None
prefect.exceptions.ParameterTypeError: Flow run received invalid parameters:
 - x: field required
 - y: field required
03:30:13.885 | INFO    | prefect.flow_runs.worker - Process 50225 exited cleanly.
